Workbook

Sheet Dashboard
A1: VSOL IT ASSET MANAGEMENT DASHBOARD | AB1: {=_xlfn._xlws.SORT(_xlfn.UNIQUE(_xlfn._xlws.FILTER(IFERROR(Detail!$AJ$2:$AJ$532,""),IFERROR(Detail!$AJ$2:$AJ$532,"")<>"")))} -> 0
A2: =CONCATENATE("Last Updated: ", TEXT(NOW(),"DD/MM/YYYY HH:MM")) -> Last Updated: 24/08/2026 09:24 | AB2: Ali Mustafa
AB3: Bùi Quốc Thái
A4: ASSET OVERVIEW (HCM & HN) | AB4: Bùi Tuấn Huy
A5: Total Devices | C5: In Use | E5: In Stock | G5: Damaged | J5: Lost | L5: Sold | AB5: Chu Văn Toàn | AC5: =IFERROR(_xlfn.XLOOKUP(B24,Detail!$AJ$2:$AJ$532,Detail!$AK$2:$AK$532,""),"") -> linhptt
A6: =COUNTIFS(Detail!B2:B532,"<>",Detail!G2:G532,"HCM")+COUNTIFS(Detail!B2:B532,"<>",Detail!G2:G532,"HN") -> 364 | C6: =COUNTIFS(Detail!C2:C532,"In Use",Detail!G2:G532,"HCM")+COUNTIFS(Detail!C2:C532,"In Use",Detail!G2:G532,"HN") -> 153 | E6: =COUNTIFS(Detail!C2:C532,"In Stock",Detail!G2:G532,"HCM")+COUNTIFS(Detail!C2:C532,"In Stock",Detail!G2:G532,"HN") -> 153 | G6: =COUNTIFS(Detail!C2:C532,"Damaged",Detail!G2:G532,"HCM")+COUNTIFS(Detail!C2:C532,"Damaged",Detail!G2:G532,"HN") -> 52 | J6: =COUNTIFS(Detail!C2:C532,"Lost",Detail!G2:G532,"HCM")+COUNTIFS(Detail!C2:C532,"Lost",Detail!G2:G532,"HN") -> 2 | L6: =COUNTIF(Detail!C:C,"Sold") -> 2 | AB6: Đặng Hồng Phong
AB7: Đặng Thành Thái
A8: DEVICES BY TYPE (HCM & HN) | J8: DEVICES BY LOCATION | AB8: Đào Đức Dũng
A9: Device Type | B9: Quantity | C9: In Use | D9: In Stock | E9: Damaged | F9: Lost | G9: Sold | H9: Warranty | J9: Location | K9: Quantity | L9: In Use | M9: In Stock | N9: Damaged | O9: Lost | P9: Sold | AB9: Đào Duy Thoại
A10: LAPTOP | B10: =COUNTIFS(Detail!B2:B532,"LAPTOP",Detail!G2:G532,"HCM")+COUNTIFS(Detail!B2:B532,"LAPTOP",Detail!G2:G532,"HN") -> 109 | C10: =COUNTIFS(Detail!B2:B532,"LAPTOP",Detail!C2:C532,"In Use",Detail!G2:G532,"HCM")+COUNTIFS(Detail!B2:B532,"LAPTOP",Detail!C2:C532,"In Use",Detail!G2:G532,"HN") -> 47 | D10: =COUNTIFS(Detail!B2:B532,"LAPTOP",Detail!C2:C532,"In Stock",Detail!G2:G532,"HCM")+COUNTIFS(Detail!B2:B532,"LAPTOP",Detail!C2:C532,"In Stock",Detail!G2:G532,"HN") -> 52 | E10: =COUNTIFS(Detail!B2:B532,"LAPTOP",Detail!C2:C532,"Damaged",Detail!G2:G532,"HCM")+COUNTIFS(Detail!B2:B532,"LAPTOP",Detail!C2:C532,"Damaged",Detail!G2:G532,"HN") -> 4 | F10: =COUNTIFS(Detail!$B$2:$B$532,$A10,Detail!$C$2:$C$532,F$9,Detail!$G$2:$G$532,"HCM")+COUNTIFS(Detail!$B$2:$B$532,$A10,Detail!$C$2:$C$532,F$9,Detail!$G$2:$G$532,"HN") -> 2 | G10: =COUNTIFS(Detail!$B$2:$B$532,$A10,Detail!$C$2:$C$532,G$9,Detail!$G$2:$G$532,"HCM")+COUNTIFS(Detail!$B$2:$B$532,$A10,Detail!$C$2:$C$532,G$9,Detail!$G$2:$G$532,"HN") -> 2 | H10: =COUNTIFS(Detail!$B$2:$B$532,$A10,Detail!$C$2:$C$532,H$9,Detail!$G$2:$G$532,"HCM")+COUNTIFS(Detail!$B$2:$B$532,$A10,Detail!$C$2:$C$532,H$9,Detail!$G$2:$G$532,"HN") -> 2 | J10: HCM | K10: =COUNTIF(Detail!G:G,"HCM") -> 355 | L10: =COUNTIFS(Detail!G:G,"HCM",Detail!C:C,"In Use") -> 152 | M10: =COUNTIFS(Detail!G:G,"HCM",Detail!C:C,"In Stock") -> 145 | N10: =COUNTIFS(Detail!G:G,"HCM",Detail!C:C,"Damaged") -> 52 | O10: =COUNTIFS(Detail!G:G,"HCM",Detail!C:C,"Lost") -> 2 | P10: =COUNTIFS(Detail!G:G,"HCM",Detail!C:C,"Sold") -> 2 | AB10: Đào Xuân Tùng
A11: MONITOR | B11: =COUNTIFS(Detail!B2:B532,"MONITOR",Detail!G2:G532,"HCM")+COUNTIFS(Detail!B2:B532,"MONITOR",Detail!G2:G532,"HN") -> 68 | C11: =COUNTIFS(Detail!B2:B532,"MONITOR",Detail!C2:C532,"In Use",Detail!G2:G532,"HCM")+COUNTIFS(Detail!B2:B532,"MONITOR",Detail!C2:C532,"In Use",Detail!G2:G532,"HN") -> 46 | D11: =COUNTIFS(Detail!B2:B532,"MONITOR",Detail!C2:C532,"In Stock",Detail!G2:G532,"HCM")+COUNTIFS(Detail!B2:B532,"MONITOR",Detail!C2:C532,"In Stock",Detail!G2:G532,"HN") -> 21 | E11: =COUNTIFS(Detail!B2:B532,"MONITOR",Detail!C2:C532,"Damaged",Detail!G2:G532,"HCM")+COUNTIFS(Detail!B2:B532,"MONITOR",Detail!C2:C532,"Damaged",Detail!G2:G532,"HN") -> 1 | F11: =COUNTIFS(Detail!$B$2:$B$532,$A11,Detail!$C$2:$C$532,F$9,Detail!$G$2:$G$532,"HCM")+COUNTIFS(Detail!$B$2:$B$532,$A11,Detail!$C$2:$C$532,F$9,Detail!$G$2:$G$532,"HN") -> 0 | G11: =COUNTIFS(Detail!$B$2:$B$532,$A11,Detail!$C$2:$C$532,G$9,Detail!$G$2:$G$532,"HCM")+COUNTIFS(Detail!$B$2:$B$532,$A11,Detail!$C$2:$C$532,G$9,Detail!$G$2:$G$532,"HN") -> 0 | H11: =COUNTIFS(Detail!$B$2:$B$532,$A11,Detail!$C$2:$C$532,H$9,Detail!$G$2:$G$532,"HCM")+COUNTIFS(Detail!$B$2:$B$532,$A11,Detail!$C$2:$C$532,H$9,Detail!$G$2:$G$532,"HN") -> 0 | J11: HN | K11: =COUNTIF(Detail!G:G,"HN") -> 9 | L11: =COUNTIFS(Detail!G:G,"HN",Detail!C:C,"In Use") -> 1 | M11: =COUNTIFS(Detail!G:G,"HN",Detail!C:C,"In Stock") -> 8 | N11: =COUNTIFS(Detail!G:G,"HN",Detail!C:C,"Damaged") -> 0 | O11: =COUNTIFS(Detail!G:G,"HN",Detail!C:C,"Lost") -> 0 | P11: =COUNTIFS(Detail!G:G,"HN",Detail!C:C,"Sold") -> 0 | AB11: Đinh Hiểu Văn
A12: MOUSE | B12: =COUNTIFS(Detail!B2:B532,"MOUSE",Detail!G2:G532,"HCM")+COUNTIFS(Detail!B2:B532,"MOUSE",Detail!G2:G532,"HN") -> 109 | C12: =COUNTIFS(Detail!B2:B532,"MOUSE",Detail!C2:C532,"In Use",Detail!G2:G532,"HCM")+COUNTIFS(Detail!B2:B532,"MOUSE",Detail!C2:C532,"In Use",Detail!G2:G532,"HN") -> 24 | D12: =COUNTIFS(Detail!B2:B532,"MOUSE",Detail!C2:C532,"In Stock",Detail!G2:G532,"HCM")+COUNTIFS(Detail!B2:B532,"MOUSE",Detail!C2:C532,"In Stock",Detail!G2:G532,"HN") -> 47 | E12: =COUNTIFS(Detail!B2:B532,"MOUSE",Detail!C2:C532,"Damaged",Detail!G2:G532,"HCM")+COUNTIFS(Detail!B2:B532,"MOUSE",Detail!C2:C532,"Damaged",Detail!G2:G532,"HN") -> 38 | F12: =COUNTIFS(Detail!$B$2:$B$532,$A12,Detail!$C$2:$C$532,F$9,Detail!$G$2:$G$532,"HCM")+COUNTIFS(Detail!$B$2:$B$532,$A12,Detail!$C$2:$C$532,F$9,Detail!$G$2:$G$532,"HN") -> 0 | G12: =COUNTIFS(Detail!$B$2:$B$532,$A12,Detail!$C$2:$C$532,G$9,Detail!$G$2:$G$532,"HCM")+COUNTIFS(Detail!$B$2:$B$532,$A12,Detail!$C$2:$C$532,G$9,Detail!$G$2:$G$532,"HN") -> 0 | H12: =COUNTIFS(Detail!$B$2:$B$532,$A12,Detail!$C$2:$C$532,H$9,Detail!$G$2:$G$532,"HCM")+COUNTIFS(Detail!$B$2:$B$532,$A12,Detail!$C$2:$C$532,H$9,Detail!$G$2:$G$532,"HN") -> 0 | J12: TOTAL | K12: =K10+K11 -> 364 | L12: =L10+L11 -> 153 | M12: =M10+M11 -> 153 | N12: =N10+N11 -> 52 | O12: =O10+O11 -> 2 | P12: =P10+P11 -> 2 | AB12: Đinh Vũ Tiến
A13: IPAD | B13: =COUNTIFS(Detail!B2:B532,"IPAD",Detail!G2:G532,"HCM")+COUNTIFS(Detail!B2:B532,"IPAD",Detail!G2:G532,"HN") -> 4 | C13: =COUNTIFS(Detail!B2:B532,"IPAD",Detail!C2:C532,"In Use",Detail!G2:G532,"HCM")+COUNTIFS(Detail!B2:B532,"IPAD",Detail!C2:C532,"In Use",Detail!G2:G532,"HN") -> 4 | D13: =COUNTIFS(Detail!B2:B532,"IPAD",Detail!C2:C532,"In Stock",Detail!G2:G532,"HCM")+COUNTIFS(Detail!B2:B532,"IPAD",Detail!C2:C532,"In Stock",Detail!G2:G532,"HN") -> 0 | E13: =COUNTIFS(Detail!B2:B532,"IPAD",Detail!C2:C532,"Damaged",Detail!G2:G532,"HCM")+COUNTIFS(Detail!B2:B532,"IPAD",Detail!C2:C532,"Damaged",Detail!G2:G532,"HN") -> 0 | F13: =COUNTIFS(Detail!$B$2:$B$532,$A13,Detail!$C$2:$C$532,F$9,Detail!$G$2:$G$532,"HCM")+COUNTIFS(Detail!$B$2:$B$532,$A13,Detail!$C$2:$C$532,F$9,Detail!$G$2:$G$532,"HN") -> 0 | G13: =COUNTIFS(Detail!$B$2:$B$532,$A13,Detail!$C$2:$C$532,G$9,Detail!$G$2:$G$532,"HCM")+COUNTIFS(Detail!$B$2:$B$532,$A13,Detail!$C$2:$C$532,G$9,Detail!$G$2:$G$532,"HN") -> 0 | H13: =COUNTIFS(Detail!$B$2:$B$532,$A13,Detail!$C$2:$C$532,H$9,Detail!$G$2:$G$532,"HCM")+COUNTIFS(Detail!$B$2:$B$532,$A13,Detail!$C$2:$C$532,H$9,Detail!$G$2:$G$532,"HN") -> 0 | AB13: Đỗ Anh Tuấn
A14: SMARTPHONE | B14: =COUNTIFS(Detail!B2:B532,"SMARTPHONE",Detail!G2:G532,"HCM")+COUNTIFS(Detail!B2:B532,"SMARTPHONE",Detail!G2:G532,"HN") -> 4 | C14: =COUNTIFS(Detail!B2:B532,"SMARTPHONE",Detail!C2:C532,"In Use",Detail!G2:G532,"HCM")+COUNTIFS(Detail!B2:B532,"SMARTPHONE",Detail!C2:C532,"In Use",Detail!G2:G532,"HN") -> 2 | D14: =COUNTIFS(Detail!B2:B532,"SMARTPHONE",Detail!C2:C532,"In Stock",Detail!G2:G532,"HCM")+COUNTIFS(Detail!B2:B532,"SMARTPHONE",Detail!C2:C532,"In Stock",Detail!G2:G532,"HN") -> 2 | E14: =COUNTIFS(Detail!B2:B532,"SMARTPHONE",Detail!C2:C532,"Damaged",Detail!G2:G532,"HCM")+COUNTIFS(Detail!B2:B532,"SMARTPHONE",Detail!C2:C532,"Damaged",Detail!G2:G532,"HN") -> 0 | F14: =COUNTIFS(Detail!$B$2:$B$532,$A14,Detail!$C$2:$C$532,F$9,Detail!$G$2:$G$532,"HCM")+COUNTIFS(Detail!$B$2:$B$532,$A14,Detail!$C$2:$C$532,F$9,Detail!$G$2:$G$532,"HN") -> 0 | G14: =COUNTIFS(Detail!$B$2:$B$532,$A14,Detail!$C$2:$C$532,G$9,Detail!$G$2:$G$532,"HCM")+COUNTIFS(Detail!$B$2:$B$532,$A14,Detail!$C$2:$C$532,G$9,Detail!$G$2:$G$532,"HN") -> 0 | H14: =COUNTIFS(Detail!$B$2:$B$532,$A14,Detail!$C$2:$C$532,H$9,Detail!$G$2:$G$532,"HCM")+COUNTIFS(Detail!$B$2:$B$532,$A14,Detail!$C$2:$C$532,H$9,Detail!$G$2:$G$532,"HN") -> 0 | AB14: Đoàn Hà Mi
A15: CABLE | B15: =COUNTIFS(Detail!B2:B532,"CABLE",Detail!G2:G532,"HCM")+COUNTIFS(Detail!B2:B532,"CABLE",Detail!G2:G532,"HN") -> 58 | C15: =COUNTIFS(Detail!B2:B532,"CABLE",Detail!C2:C532,"In Use",Detail!G2:G532,"HCM")+COUNTIFS(Detail!B2:B532,"CABLE",Detail!C2:C532,"In Use",Detail!G2:G532,"HN") -> 23 | D15: =COUNTIFS(Detail!B2:B532,"CABLE",Detail!C2:C532,"In Stock",Detail!G2:G532,"HCM")+COUNTIFS(Detail!B2:B532,"CABLE",Detail!C2:C532,"In Stock",Detail!G2:G532,"HN") -> 30 | E15: =COUNTIFS(Detail!B2:B532,"CABLE",Detail!C2:C532,"Damaged",Detail!G2:G532,"HCM")+COUNTIFS(Detail!B2:B532,"CABLE",Detail!C2:C532,"Damaged",Detail!G2:G532,"HN") -> 5 | F15: =COUNTIFS(Detail!$B$2:$B$532,$A15,Detail!$C$2:$C$532,F$9,Detail!$G$2:$G$532,"HCM")+COUNTIFS(Detail!$B$2:$B$532,$A15,Detail!$C$2:$C$532,F$9,Detail!$G$2:$G$532,"HN") -> 0 | G15: =COUNTIFS(Detail!$B$2:$B$532,$A15,Detail!$C$2:$C$532,G$9,Detail!$G$2:$G$532,"HCM")+COUNTIFS(Detail!$B$2:$B$532,$A15,Detail!$C$2:$C$532,G$9,Detail!$G$2:$G$532,"HN") -> 0 | H15: =COUNTIFS(Detail!$B$2:$B$532,$A15,Detail!$C$2:$C$532,H$9,Detail!$G$2:$G$532,"HCM")+COUNTIFS(Detail!$B$2:$B$532,$A15,Detail!$C$2:$C$532,H$9,Detail!$G$2:$G$532,"HN") -> 0 | J15: DEVICES BY BUSINESS UNIT (HCM & HN) | AB15: Đoàn Hải Nam
A16: SSD | B16: =COUNTIFS(Detail!B2:B532,"SSD",Detail!G2:G532,"HCM")+COUNTIFS(Detail!B2:B532,"SSD",Detail!G2:G532,"HN") -> 4 | C16: =COUNTIFS(Detail!B2:B532,"SSD",Detail!C2:C532,"In Use",Detail!G2:G532,"HCM")+COUNTIFS(Detail!B2:B532,"SSD",Detail!C2:C532,"In Use",Detail!G2:G532,"HN") -> 2 | D16: =COUNTIFS(Detail!B2:B532,"SSD",Detail!C2:C532,"In Stock",Detail!G2:G532,"HCM")+COUNTIFS(Detail!B2:B532,"SSD",Detail!C2:C532,"In Stock",Detail!G2:G532,"HN") -> 0 | E16: =COUNTIFS(Detail!B2:B532,"SSD",Detail!C2:C532,"Damaged",Detail!G2:G532,"HCM")+COUNTIFS(Detail!B2:B532,"SSD",Detail!C2:C532,"Damaged",Detail!G2:G532,"HN") -> 2 | F16: =COUNTIFS(Detail!$B$2:$B$532,$A16,Detail!$C$2:$C$532,F$9,Detail!$G$2:$G$532,"HCM")+COUNTIFS(Detail!$B$2:$B$532,$A16,Detail!$C$2:$C$532,F$9,Detail!$G$2:$G$532,"HN") -> 0 | G16: =COUNTIFS(Detail!$B$2:$B$532,$A16,Detail!$C$2:$C$532,G$9,Detail!$G$2:$G$532,"HCM")+COUNTIFS(Detail!$B$2:$B$532,$A16,Detail!$C$2:$C$532,G$9,Detail!$G$2:$G$532,"HN") -> 0 | H16: =COUNTIFS(Detail!$B$2:$B$532,$A16,Detail!$C$2:$C$532,H$9,Detail!$G$2:$G$532,"HCM")+COUNTIFS(Detail!$B$2:$B$532,$A16,Detail!$C$2:$C$532,H$9,Detail!$G$2:$G$532,"HN") -> 0 | J16: Business Unit | K16: Quantity | L16: In Use | M16: In Stock | N16: Damaged | O16: Lost | P16: Sold | AB16: Đoàn Nhật Duẩn
A17: RAM | B17: =COUNTIFS(Detail!B2:B532,"RAM",Detail!G2:G532,"HCM")+COUNTIFS(Detail!B2:B532,"RAM",Detail!G2:G532,"HN") -> 2 | C17: =COUNTIFS(Detail!B2:B532,"RAM",Detail!C2:C532,"In Use",Detail!G2:G532,"HCM")+COUNTIFS(Detail!B2:B532,"RAM",Detail!C2:C532,"In Use",Detail!G2:G532,"HN") -> 0 | D17: =COUNTIFS(Detail!B2:B532,"RAM",Detail!C2:C532,"In Stock",Detail!G2:G532,"HCM")+COUNTIFS(Detail!B2:B532,"RAM",Detail!C2:C532,"In Stock",Detail!G2:G532,"HN") -> 0 | E17: =COUNTIFS(Detail!B2:B532,"RAM",Detail!C2:C532,"Damaged",Detail!G2:G532,"HCM")+COUNTIFS(Detail!B2:B532,"RAM",Detail!C2:C532,"Damaged",Detail!G2:G532,"HN") -> 2 | F17: =COUNTIFS(Detail!$B$2:$B$532,$A17,Detail!$C$2:$C$532,F$9,Detail!$G$2:$G$532,"HCM")+COUNTIFS(Detail!$B$2:$B$532,$A17,Detail!$C$2:$C$532,F$9,Detail!$G$2:$G$532,"HN") -> 0 | G17: =COUNTIFS(Detail!$B$2:$B$532,$A17,Detail!$C$2:$C$532,G$9,Detail!$G$2:$G$532,"HCM")+COUNTIFS(Detail!$B$2:$B$532,$A17,Detail!$C$2:$C$532,G$9,Detail!$G$2:$G$532,"HN") -> 0 | H17: =COUNTIFS(Detail!$B$2:$B$532,$A17,Detail!$C$2:$C$532,H$9,Detail!$G$2:$G$532,"HCM")+COUNTIFS(Detail!$B$2:$B$532,$A17,Detail!$C$2:$C$532,H$9,Detail!$G$2:$G$532,"HN") -> 0 | J17: Project | K17: =COUNTIFS(Detail!D:D,"Project",Detail!G:G,"HCM")+COUNTIFS(Detail!D:D,"Project",Detail!G:G,"HN") -> 89 | L17: =COUNTIFS(Detail!D:D,"Project",Detail!C:C,"In Use",Detail!G:G,"HCM")+COUNTIFS(Detail!D:D,"Project",Detail!C:C,"In Use",Detail!G:G,"HN") -> 84 | M17: =COUNTIFS(Detail!D:D,"Project",Detail!C:C,"In Stock",Detail!G:G,"HCM")+COUNTIFS(Detail!D:D,"Project",Detail!C:C,"In Stock",Detail!G:G,"HN") -> 1 | N17: =COUNTIFS(Detail!D:D,"Project",Detail!C:C,"Damaged",Detail!G:G,"HCM")+COUNTIFS(Detail!D:D,"Project",Detail!C:C,"Damaged",Detail!G:G,"HN") -> 4 | O17: =COUNTIFS(Detail!D:D,"Project",Detail!C:C,"Lost",Detail!G:G,"HCM")+COUNTIFS(Detail!D:D,"Project",Detail!C:C,"Lost",Detail!G:G,"HN") -> 0 | P17: =COUNTIFS(Detail!D:D,"Project",Detail!C:C,"Sold",Detail!G:G,"HCM")+COUNTIFS(Detail!D:D,"Project",Detail!C:C,"Sold",Detail!G:G,"HN") -> 0 | AB17: Dương Phạm Thành Công
A18: CPU | B18: =COUNTIFS(Detail!B2:B532,"CPU",Detail!G2:G532,"HCM")+COUNTIFS(Detail!B2:B532,"CPU",Detail!G2:G532,"HN") -> 2 | C18: =COUNTIFS(Detail!B2:B532,"CPU",Detail!C2:C532,"In Use",Detail!G2:G532,"HCM")+COUNTIFS(Detail!B2:B532,"CPU",Detail!C2:C532,"In Use",Detail!G2:G532,"HN") -> 2 | D18: =COUNTIFS(Detail!B2:B532,"CPU",Detail!C2:C532,"In Stock",Detail!G2:G532,"HCM")+COUNTIFS(Detail!B2:B532,"CPU",Detail!C2:C532,"In Stock",Detail!G2:G532,"HN") -> 0 | E18: =COUNTIFS(Detail!B2:B532,"CPU",Detail!C2:C532,"Damaged",Detail!G2:G532,"HCM")+COUNTIFS(Detail!B2:B532,"CPU",Detail!C2:C532,"Damaged",Detail!G2:G532,"HN") -> 0 | F18: =COUNTIFS(Detail!$B$2:$B$532,$A18,Detail!$C$2:$C$532,F$9,Detail!$G$2:$G$532,"HCM")+COUNTIFS(Detail!$B$2:$B$532,$A18,Detail!$C$2:$C$532,F$9,Detail!$G$2:$G$532,"HN") -> 0 | G18: =COUNTIFS(Detail!$B$2:$B$532,$A18,Detail!$C$2:$C$532,G$9,Detail!$G$2:$G$532,"HCM")+COUNTIFS(Detail!$B$2:$B$532,$A18,Detail!$C$2:$C$532,G$9,Detail!$G$2:$G$532,"HN") -> 0 | H18: =COUNTIFS(Detail!$B$2:$B$532,$A18,Detail!$C$2:$C$532,H$9,Detail!$G$2:$G$532,"HCM")+COUNTIFS(Detail!$B$2:$B$532,$A18,Detail!$C$2:$C$532,H$9,Detail!$G$2:$G$532,"HN") -> 0 | J18: BO | K18: =COUNTIFS(Detail!D:D,"BO",Detail!G:G,"HCM")+COUNTIFS(Detail!D:D,"BO",Detail!G:G,"HN") -> 30 | L18: =COUNTIFS(Detail!D:D,"BO",Detail!C:C,"In Use",Detail!G:G,"HCM")+COUNTIFS(Detail!D:D,"BO",Detail!C:C,"In Use",Detail!G:G,"HN") -> 25 | M18: =COUNTIFS(Detail!D:D,"BO",Detail!C:C,"In Stock",Detail!G:G,"HCM")+COUNTIFS(Detail!D:D,"BO",Detail!C:C,"In Stock",Detail!G:G,"HN") -> 5 | N18: =COUNTIFS(Detail!D:D,"BO",Detail!C:C,"Damaged",Detail!G:G,"HCM")+COUNTIFS(Detail!D:D,"BO",Detail!C:C,"Damaged",Detail!G:G,"HN") -> 0 | O18: =COUNTIFS(Detail!D:D,"BO",Detail!C:C,"Lost",Detail!G:G,"HCM")+COUNTIFS(Detail!D:D,"BO",Detail!C:C,"Lost",Detail!G:G,"HN") -> 0 | P18: =COUNTIFS(Detail!D:D,"BO",Detail!C:C,"Sold",Detail!G:G,"HCM")+COUNTIFS(Detail!D:D,"BO",Detail!C:C,"Sold",Detail!G:G,"HN") -> 0 | AB18: Gary Robert Charles Mckinnon
A19: ROUTER | B19: =COUNTIFS(Detail!B2:B532,"ROUTER",Detail!G2:G532,"HCM")+COUNTIFS(Detail!B2:B532,"ROUTER",Detail!G2:G532,"HN") -> 3 | C19: =COUNTIFS(Detail!B2:B532,"ROUTER",Detail!C2:C532,"In Use",Detail!G2:G532,"HCM")+COUNTIFS(Detail!B2:B532,"ROUTER",Detail!C2:C532,"In Use",Detail!G2:G532,"HN") -> 2 | D19: =COUNTIFS(Detail!B2:B532,"ROUTER",Detail!C2:C532,"In Stock",Detail!G2:G532,"HCM")+COUNTIFS(Detail!B2:B532,"ROUTER",Detail!C2:C532,"In Stock",Detail!G2:G532,"HN") -> 1 | E19: =COUNTIFS(Detail!B2:B532,"ROUTER",Detail!C2:C532,"Damaged",Detail!G2:G532,"HCM")+COUNTIFS(Detail!B2:B532,"ROUTER",Detail!C2:C532,"Damaged",Detail!G2:G532,"HN") -> 0 | F19: =COUNTIFS(Detail!$B$2:$B$532,$A19,Detail!$C$2:$C$532,F$9,Detail!$G$2:$G$532,"HCM")+COUNTIFS(Detail!$B$2:$B$532,$A19,Detail!$C$2:$C$532,F$9,Detail!$G$2:$G$532,"HN") -> 0 | G19: =COUNTIFS(Detail!$B$2:$B$532,$A19,Detail!$C$2:$C$532,G$9,Detail!$G$2:$G$532,"HCM")+COUNTIFS(Detail!$B$2:$B$532,$A19,Detail!$C$2:$C$532,G$9,Detail!$G$2:$G$532,"HN") -> 0 | H19: =COUNTIFS(Detail!$B$2:$B$532,$A19,Detail!$C$2:$C$532,H$9,Detail!$G$2:$G$532,"HCM")+COUNTIFS(Detail!$B$2:$B$532,$A19,Detail!$C$2:$C$532,H$9,Detail!$G$2:$G$532,"HN") -> 0 | J19: CTD | K19: =COUNTIFS(Detail!D:D,"CTD",Detail!G:G,"HCM")+COUNTIFS(Detail!D:D,"CTD",Detail!G:G,"HN") -> 20 | L19: =COUNTIFS(Detail!D:D,"CTD",Detail!C:C,"In Use",Detail!G:G,"HCM")+COUNTIFS(Detail!D:D,"CTD",Detail!C:C,"In Use",Detail!G:G,"HN") -> 20 | M19: =COUNTIFS(Detail!D:D,"CTD",Detail!C:C,"In Stock",Detail!G:G,"HCM")+COUNTIFS(Detail!D:D,"CTD",Detail!C:C,"In Stock",Detail!G:G,"HN") -> 0 | N19: =COUNTIFS(Detail!D:D,"CTD",Detail!C:C,"Damaged",Detail!G:G,"HCM")+COUNTIFS(Detail!D:D,"CTD",Detail!C:C,"Damaged",Detail!G:G,"HN") -> 0 | O19: =COUNTIFS(Detail!D:D,"CTD",Detail!C:C,"Lost",Detail!G:G,"HCM")+COUNTIFS(Detail!D:D,"CTD",Detail!C:C,"Lost",Detail!G:G,"HN") -> 0 | P19: =COUNTIFS(Detail!D:D,"CTD",Detail!C:C,"Sold",Detail!G:G,"HCM")+COUNTIFS(Detail!D:D,"CTD",Detail!C:C,"Sold",Detail!G:G,"HN") -> 0 | AB19: Hà Quốc Nguyên
A20: PRINTER | B20: =COUNTIFS(Detail!B2:B532,"PRINTER",Detail!G2:G532,"HCM")+COUNTIFS(Detail!B2:B532,"PRINTER",Detail!G2:G532,"HN") -> 1 | C20: =COUNTIFS(Detail!B2:B532,"PRINTER",Detail!C2:C532,"In Use",Detail!G2:G532,"HCM")+COUNTIFS(Detail!B2:B532,"PRINTER",Detail!C2:C532,"In Use",Detail!G2:G532,"HN") -> 1 | D20: =COUNTIFS(Detail!B2:B532,"PRINTER",Detail!C2:C532,"In Stock",Detail!G2:G532,"HCM")+COUNTIFS(Detail!B2:B532,"PRINTER",Detail!C2:C532,"In Stock",Detail!G2:G532,"HN") -> 0 | E20: =COUNTIFS(Detail!B2:B532,"PRINTER",Detail!C2:C532,"Damaged",Detail!G2:G532,"HCM")+COUNTIFS(Detail!B2:B532,"PRINTER",Detail!C2:C532,"Damaged",Detail!G2:G532,"HN") -> 0 | F20: =COUNTIFS(Detail!$B$2:$B$532,$A20,Detail!$C$2:$C$532,F$9,Detail!$G$2:$G$532,"HCM")+COUNTIFS(Detail!$B$2:$B$532,$A20,Detail!$C$2:$C$532,F$9,Detail!$G$2:$G$532,"HN") -> 0 | G20: =COUNTIFS(Detail!$B$2:$B$532,$A20,Detail!$C$2:$C$532,G$9,Detail!$G$2:$G$532,"HCM")+COUNTIFS(Detail!$B$2:$B$532,$A20,Detail!$C$2:$C$532,G$9,Detail!$G$2:$G$532,"HN") -> 0 | H20: =COUNTIFS(Detail!$B$2:$B$532,$A20,Detail!$C$2:$C$532,H$9,Detail!$G$2:$G$532,"HCM")+COUNTIFS(Detail!$B$2:$B$532,$A20,Detail!$C$2:$C$532,H$9,Detail!$G$2:$G$532,"HN") -> 0 | J20: AM | K20: =COUNTIFS(Detail!D:D,"AM",Detail!G:G,"HCM")+COUNTIFS(Detail!D:D,"AM",Detail!G:G,"HN") -> 3 | L20: =COUNTIFS(Detail!D:D,"AM",Detail!C:C,"In Use",Detail!G:G,"HCM")+COUNTIFS(Detail!D:D,"AM",Detail!C:C,"In Use",Detail!G:G,"HN") -> 3 | M20: =COUNTIFS(Detail!D:D,"AM",Detail!C:C,"In Stock",Detail!G:G,"HCM")+COUNTIFS(Detail!D:D,"AM",Detail!C:C,"In Stock",Detail!G:G,"HN") -> 0 | N20: =COUNTIFS(Detail!D:D,"AM",Detail!C:C,"Damaged",Detail!G:G,"HCM")+COUNTIFS(Detail!D:D,"AM",Detail!C:C,"Damaged",Detail!G:G,"HN") -> 0 | O20: =COUNTIFS(Detail!D:D,"AM",Detail!C:C,"Lost",Detail!G:G,"HCM")+COUNTIFS(Detail!D:D,"AM",Detail!C:C,"Lost",Detail!G:G,"HN") -> 0 | P20: =COUNTIFS(Detail!D:D,"AM",Detail!C:C,"Sold",Detail!G:G,"HCM")+COUNTIFS(Detail!D:D,"AM",Detail!C:C,"Sold",Detail!G:G,"HN") -> 0 | AB20: Hồ Ngọc Danh
A21: SPEAKER | B21: =COUNTIFS(Detail!B2:B532,"SPEAKER",Detail!G2:G532,"HCM")+COUNTIFS(Detail!B2:B532,"SPEAKER",Detail!G2:G532,"HN") -> 0 | C21: =COUNTIFS(Detail!B2:B532,"SPEAKER",Detail!C2:C532,"In Use",Detail!G2:G532,"HCM")+COUNTIFS(Detail!B2:B532,"SPEAKER",Detail!C2:C532,"In Use",Detail!G2:G532,"HN") -> 0 | D21: =COUNTIFS(Detail!B2:B532,"SPEAKER",Detail!C2:C532,"In Stock",Detail!G2:G532,"HCM")+COUNTIFS(Detail!B2:B532,"SPEAKER",Detail!C2:C532,"In Stock",Detail!G2:G532,"HN") -> 0 | E21: =COUNTIFS(Detail!B2:B532,"SPEAKER",Detail!C2:C532,"Damaged",Detail!G2:G532,"HCM")+COUNTIFS(Detail!B2:B532,"SPEAKER",Detail!C2:C532,"Damaged",Detail!G2:G532,"HN") -> 0 | F21: =COUNTIFS(Detail!$B$2:$B$532,$A21,Detail!$C$2:$C$532,F$9,Detail!$G$2:$G$532,"HCM")+COUNTIFS(Detail!$B$2:$B$532,$A21,Detail!$C$2:$C$532,F$9,Detail!$G$2:$G$532,"HN") -> 0 | G21: =COUNTIFS(Detail!$B$2:$B$532,$A21,Detail!$C$2:$C$532,G$9,Detail!$G$2:$G$532,"HCM")+COUNTIFS(Detail!$B$2:$B$532,$A21,Detail!$C$2:$C$532,G$9,Detail!$G$2:$G$532,"HN") -> 0 | H21: =COUNTIFS(Detail!$B$2:$B$532,$A21,Detail!$C$2:$C$532,H$9,Detail!$G$2:$G$532,"HCM")+COUNTIFS(Detail!$B$2:$B$532,$A21,Detail!$C$2:$C$532,H$9,Detail!$G$2:$G$532,"HN") -> 0 | J21: Undirect IT Staff | K21: =COUNTIFS(Detail!D:D,"Undirect IT Staff",Detail!G:G,"HCM")+COUNTIFS(Detail!D:D,"Undirect IT Staff",Detail!G:G,"HN") -> 22 | L21: =COUNTIFS(Detail!D:D,"Undirect IT Staff",Detail!C:C,"In Use",Detail!G:G,"HCM")+COUNTIFS(Detail!D:D,"Undirect IT Staff",Detail!C:C,"In Use",Detail!G:G,"HN") -> 17 | M21: =COUNTIFS(Detail!D:D,"Undirect IT Staff",Detail!C:C,"In Stock",Detail!G:G,"HCM")+COUNTIFS(Detail!D:D,"Undirect IT Staff",Detail!C:C,"In Stock",Detail!G:G,"HN") -> 3 | N21: =COUNTIFS(Detail!D:D,"Undirect IT Staff",Detail!C:C,"Damaged",Detail!G:G,"HCM")+COUNTIFS(Detail!D:D,"Undirect IT Staff",Detail!C:C,"Damaged",Detail!G:G,"HN") -> 2 | O21: =COUNTIFS(Detail!D:D,"Undirect IT Staff",Detail!C:C,"Lost",Detail!G:G,"HCM")+COUNTIFS(Detail!D:D,"Undirect IT Staff",Detail!C:C,"Lost",Detail!G:G,"HN") -> 0 | P21: =COUNTIFS(Detail!D:D,"Undirect IT Staff",Detail!C:C,"Sold",Detail!G:G,"HCM")+COUNTIFS(Detail!D:D,"Undirect IT Staff",Detail!C:C,"Sold",Detail!G:G,"HN") -> 0 | AB21: Hoàng Anh Dũng
AB22: Hoàng Thị Trang
A23: EMPLOYEE ASSET LOOKUP (HCM & HN) | J23: LAPTOP DETAILS BY CHIP & STORAGE (HCM & HN) | AB23: Huỳnh Nguyên Phương
A24: Select Employee: | B24: Phạm Thị Trúc Linh | J24: By Chip | AB24: Huỳnh Quốc Quân
J25: Chip | K25: Quantity | L25: In Use | M25: In Stock | N25: Damaged | O25: Lost | P25: Sold | AB25: Huỳnh Thúy Diễm
A26: Old Label | B26: Label | C26: Type | D26: Description | E26: Serial Number | F26: Location | G26: Status | J26: M1 | K26: =COUNTIFS(Detail!B:B,"LAPTOP",Detail!L:L,"M1",Detail!G:G,"HCM")+COUNTIFS(Detail!B:B,"LAPTOP",Detail!L:L,"M1",Detail!G:G,"HN") -> 14 | L26: =COUNTIFS(Detail!B:B,"LAPTOP",Detail!L:L,"M1",Detail!C:C,"In Use",Detail!G:G,"HCM")+COUNTIFS(Detail!B:B,"LAPTOP",Detail!L:L,"M1",Detail!C:C,"In Use",Detail!G:G,"HN") -> 5 | M26: =COUNTIFS(Detail!B:B,"LAPTOP",Detail!L:L,"M1",Detail!C:C,"In Stock",Detail!G:G,"HCM")+COUNTIFS(Detail!B:B,"LAPTOP",Detail!L:L,"M1",Detail!C:C,"In Stock",Detail!G:G,"HN") -> 8 | N26: =COUNTIFS(Detail!B:B,"LAPTOP",Detail!L:L,"M1",Detail!C:C,"Damaged",Detail!G:G,"HCM")+COUNTIFS(Detail!B:B,"LAPTOP",Detail!L:L,"M1",Detail!C:C,"Damaged",Detail!G:G,"HN") -> 1 | O26: =COUNTIFS(Detail!B:B,"LAPTOP",Detail!L:L,"M1",Detail!C:C,"Lost",Detail!G:G,"HCM")+COUNTIFS(Detail!B:B,"LAPTOP",Detail!L:L,"M1",Detail!C:C,"Lost",Detail!G:G,"HN") -> 0 | P26: =COUNTIFS(Detail!B:B,"LAPTOP",Detail!L:L,"M1",Detail!C:C,"Sold",Detail!G:G,"HCM")+COUNTIFS(Detail!B:B,"LAPTOP",Detail!L:L,"M1",Detail!C:C,"Sold",Detail!G:G,"HN") -> 0 | AB26: IPL Meeting Room
A27: {=IF(B24="","Select an employee",IFERROR(_xlfn._xlws.FILTER(_xlfn.HSTACK(IF(Detail!$H$2:$H$532=0,"",Detail!$H$2:$H$532),Detail!$I$2:$I$532,Detail!$B$2:$B$532,IF(Detail!$K$2:$K$532=0,"",Detail!$K$2:$K$532),IF(Detail!$P$2:$P$532=0,"",Detail!$P$2:$P$532),Detail!$G$2:$G$532,Detail!$C$2:$C$532),(Detail!$AK$2:$AK$532=$AC$5)*(Detail!$C$2:$C$532="In Use")*((Detail!$G$2:$G$532="HCM")+(Detail!$G$2:$G$532="HN")),"No assets found"),"No assets found"))} | B27: LAP0062 | C27: LAPTOP | D27: Macbook Pro M2 16GB | 256GB | E27: YQX1W3H610 | F27: HCM | G27: In Use | J27: M2 | K27: =COUNTIFS(Detail!B:B,"LAPTOP",Detail!L:L,"M2",Detail!G:G,"HCM")+COUNTIFS(Detail!B:B,"LAPTOP",Detail!L:L,"M2",Detail!G:G,"HN") -> 5 | L27: =COUNTIFS(Detail!B:B,"LAPTOP",Detail!L:L,"M2",Detail!C:C,"In Use",Detail!G:G,"HCM")+COUNTIFS(Detail!B:B,"LAPTOP",Detail!L:L,"M2",Detail!C:C,"In Use",Detail!G:G,"HN") -> 5 | M27: =COUNTIFS(Detail!B:B,"LAPTOP",Detail!L:L,"M2",Detail!C:C,"In Stock",Detail!G:G,"HCM")+COUNTIFS(Detail!B:B,"LAPTOP",Detail!L:L,"M2",Detail!C:C,"In Stock",Detail!G:G,"HN") -> 0 | N27: =COUNTIFS(Detail!B:B,"LAPTOP",Detail!L:L,"M2",Detail!C:C,"Damaged",Detail!G:G,"HCM")+COUNTIFS(Detail!B:B,"LAPTOP",Detail!L:L,"M2",Detail!C:C,"Damaged",Detail!G:G,"HN") -> 0 | O27: =COUNTIFS(Detail!B:B,"LAPTOP",Detail!L:L,"M2",Detail!C:C,"Lost",Detail!G:G,"HCM")+COUNTIFS(Detail!B:B,"LAPTOP",Detail!L:L,"M2",Detail!C:C,"Lost",Detail!G:G,"HN") -> 0 | P27: =COUNTIFS(Detail!B:B,"LAPTOP",Detail!L:L,"M2",Detail!C:C,"Sold",Detail!G:G,"HCM")+COUNTIFS(Detail!B:B,"LAPTOP",Detail!L:L,"M2",Detail!C:C,"Sold",Detail!G:G,"HN") -> 0 | AB27: IT Dept CTD
B28: MOU0021 | C28: MOUSE | D28: Logitech M221 | E28: 2445ZEW5H0K8 | F28: HCM | G28: In Use | J28: M3 | K28: =COUNTIFS(Detail!B:B,"LAPTOP",Detail!L:L,"M3",Detail!G:G,"HCM")+COUNTIFS(Detail!B:B,"LAPTOP",Detail!L:L,"M3",Detail!G:G,"HN") -> 3 | L28: =COUNTIFS(Detail!B:B,"LAPTOP",Detail!L:L,"M3",Detail!C:C,"In Use",Detail!G:G,"HCM")+COUNTIFS(Detail!B:B,"LAPTOP",Detail!L:L,"M3",Detail!C:C,"In Use",Detail!G:G,"HN") -> 2 | M28: =COUNTIFS(Detail!B:B,"LAPTOP",Detail!L:L,"M3",Detail!C:C,"In Stock",Detail!G:G,"HCM")+COUNTIFS(Detail!B:B,"LAPTOP",Detail!L:L,"M3",Detail!C:C,"In Stock",Detail!G:G,"HN") -> 1 | N28: =COUNTIFS(Detail!B:B,"LAPTOP",Detail!L:L,"M3",Detail!C:C,"Damaged",Detail!G:G,"HCM")+COUNTIFS(Detail!B:B,"LAPTOP",Detail!L:L,"M3",Detail!C:C,"Damaged",Detail!G:G,"HN") -> 0 | O28: =COUNTIFS(Detail!B:B,"LAPTOP",Detail!L:L,"M3",Detail!C:C,"Lost",Detail!G:G,"HCM")+COUNTIFS(Detail!B:B,"LAPTOP",Detail!L:L,"M3",Detail!C:C,"Lost",Detail!G:G,"HN") -> 0 | P28: =COUNTIFS(Detail!B:B,"LAPTOP",Detail!L:L,"M3",Detail!C:C,"Sold",Detail!G:G,"HCM")+COUNTIFS(Detail!B:B,"LAPTOP",Detail!L:L,"M3",Detail!C:C,"Sold",Detail!G:G,"HN") -> 0 | AB28: Ivan
A29: MON16276 | B29: MON0052 | C29: MONITOR | D29: Dell P2425H 24 inches | E29: 8BF2L34 | F29: HCM | G29: In Use | J29: M4 | K29: =COUNTIFS(Detail!B:B,"LAPTOP",Detail!L:L,"M4",Detail!G:G,"HCM")+COUNTIFS(Detail!B:B,"LAPTOP",Detail!L:L,"M4",Detail!G:G,"HN") -> 20 | L29: =COUNTIFS(Detail!B:B,"LAPTOP",Detail!L:L,"M4",Detail!C:C,"In Use",Detail!G:G,"HCM")+COUNTIFS(Detail!B:B,"LAPTOP",Detail!L:L,"M4",Detail!C:C,"In Use",Detail!G:G,"HN") -> 17 | M29: =COUNTIFS(Detail!B:B,"LAPTOP",Detail!L:L,"M4",Detail!C:C,"In Stock",Detail!G:G,"HCM")+COUNTIFS(Detail!B:B,"LAPTOP",Detail!L:L,"M4",Detail!C:C,"In Stock",Detail!G:G,"HN") -> 1 | N29: =COUNTIFS(Detail!B:B,"LAPTOP",Detail!L:L,"M4",Detail!C:C,"Damaged",Detail!G:G,"HCM")+COUNTIFS(Detail!B:B,"LAPTOP",Detail!L:L,"M4",Detail!C:C,"Damaged",Detail!G:G,"HN") -> 0 | O29: =COUNTIFS(Detail!B:B,"LAPTOP",Detail!L:L,"M4",Detail!C:C,"Lost",Detail!G:G,"HCM")+COUNTIFS(Detail!B:B,"LAPTOP",Detail!L:L,"M4",Detail!C:C,"Lost",Detail!G:G,"HN") -> 0 | P29: =COUNTIFS(Detail!B:B,"LAPTOP",Detail!L:L,"M4",Detail!C:C,"Sold",Detail!G:G,"HCM")+COUNTIFS(Detail!B:B,"LAPTOP",Detail!L:L,"M4",Detail!C:C,"Sold",Detail!G:G,"HN") -> 0 | AB29: Khổng Gia Bình
B30: CAB0066 | C30: CABLE | D30: Ugreen USB-C multifunction adapter | F30: HCM | G30: In Use | J30: i5 | K30: =COUNTIFS(Detail!B:B,"LAPTOP",Detail!L:L,"i5",Detail!G:G,"HCM")+COUNTIFS(Detail!B:B,"LAPTOP",Detail!L:L,"i5",Detail!G:G,"HN") -> 50 | L30: =COUNTIFS(Detail!B:B,"LAPTOP",Detail!L:L,"i5",Detail!C:C,"In Use",Detail!G:G,"HCM")+COUNTIFS(Detail!B:B,"LAPTOP",Detail!L:L,"i5",Detail!C:C,"In Use",Detail!G:G,"HN") -> 12 | M30: =COUNTIFS(Detail!B:B,"LAPTOP",Detail!L:L,"i5",Detail!C:C,"In Stock",Detail!G:G,"HCM")+COUNTIFS(Detail!B:B,"LAPTOP",Detail!L:L,"i5",Detail!C:C,"In Stock",Detail!G:G,"HN") -> 32 | N30: =COUNTIFS(Detail!B:B,"LAPTOP",Detail!L:L,"i5",Detail!C:C,"Damaged",Detail!G:G,"HCM")+COUNTIFS(Detail!B:B,"LAPTOP",Detail!L:L,"i5",Detail!C:C,"Damaged",Detail!G:G,"HN") -> 3 | O30: =COUNTIFS(Detail!B:B,"LAPTOP",Detail!L:L,"i5",Detail!C:C,"Lost",Detail!G:G,"HCM")+COUNTIFS(Detail!B:B,"LAPTOP",Detail!L:L,"i5",Detail!C:C,"Lost",Detail!G:G,"HN") -> 2 | P30: =COUNTIFS(Detail!B:B,"LAPTOP",Detail!L:L,"i5",Detail!C:C,"Sold",Detail!G:G,"HCM")+COUNTIFS(Detail!B:B,"LAPTOP",Detail!L:L,"i5",Detail!C:C,"Sold",Detail!G:G,"HN") -> 1 | AB30: Kiết Văn
J31: i7 | K31: =COUNTIFS(Detail!B:B,"LAPTOP",Detail!L:L,"i7",Detail!G:G,"HCM")+COUNTIFS(Detail!B:B,"LAPTOP",Detail!L:L,"i7",Detail!G:G,"HN") -> 17 | L31: =COUNTIFS(Detail!B:B,"LAPTOP",Detail!L:L,"i7",Detail!C:C,"In Use",Detail!G:G,"HCM")+COUNTIFS(Detail!B:B,"LAPTOP",Detail!L:L,"i7",Detail!C:C,"In Use",Detail!G:G,"HN") -> 6 | M31: =COUNTIFS(Detail!B:B,"LAPTOP",Detail!L:L,"i7",Detail!C:C,"In Stock",Detail!G:G,"HCM")+COUNTIFS(Detail!B:B,"LAPTOP",Detail!L:L,"i7",Detail!C:C,"In Stock",Detail!G:G,"HN") -> 10 | N31: =COUNTIFS(Detail!B:B,"LAPTOP",Detail!L:L,"i7",Detail!C:C,"Damaged",Detail!G:G,"HCM")+COUNTIFS(Detail!B:B,"LAPTOP",Detail!L:L,"i7",Detail!C:C,"Damaged",Detail!G:G,"HN") -> 0 | O31: =COUNTIFS(Detail!B:B,"LAPTOP",Detail!L:L,"i7",Detail!C:C,"Lost",Detail!G:G,"HCM")+COUNTIFS(Detail!B:B,"LAPTOP",Detail!L:L,"i7",Detail!C:C,"Lost",Detail!G:G,"HN") -> 0 | P31: =COUNTIFS(Detail!B:B,"LAPTOP",Detail!L:L,"i7",Detail!C:C,"Sold",Detail!G:G,"HCM")+COUNTIFS(Detail!B:B,"LAPTOP",Detail!L:L,"i7",Detail!C:C,"Sold",Detail!G:G,"HN") -> 1 | AB31: Lại Thế Cường
J32: By Storage | AB32: Lê Cao Long Nhật
J33: Storage | K33: Quantity | L33: In Use | M33: In Stock | N33: Damaged | O33: Lost | P33: Sold | AB33: Lê Nam Hưng
J34: 256GB | K34: =COUNTIFS(Detail!B:B,"LAPTOP",Detail!M:M,"*256GB*",Detail!G:G,"HCM")+COUNTIFS(Detail!B:B,"LAPTOP",Detail!M:M,"*256GB*",Detail!G:G,"HN") -> 69 | L34: =COUNTIFS(Detail!B:B,"LAPTOP",Detail!M:M,"*256GB*",Detail!C:C,"In Use",Detail!G:G,"HCM")+COUNTIFS(Detail!B:B,"LAPTOP",Detail!M:M,"*256GB*",Detail!C:C,"In Use",Detail!G:G,"HN") -> 22 | M34: =COUNTIFS(Detail!B:B,"LAPTOP",Detail!M:M,"*256GB*",Detail!C:C,"In Stock",Detail!G:G,"HCM")+COUNTIFS(Detail!B:B,"LAPTOP",Detail!M:M,"*256GB*",Detail!C:C,"In Stock",Detail!G:G,"HN") -> 40 | N34: =COUNTIFS(Detail!B:B,"LAPTOP",Detail!M:M,"*256GB*",Detail!C:C,"Damaged",Detail!G:G,"HCM")+COUNTIFS(Detail!B:B,"LAPTOP",Detail!M:M,"*256GB*",Detail!C:C,"Damaged",Detail!G:G,"HN") -> 4 | O34: =COUNTIFS(Detail!B:B,"LAPTOP",Detail!M:M,"*256GB*",Detail!C:C,"Lost",Detail!G:G,"HCM")+COUNTIFS(Detail!B:B,"LAPTOP",Detail!M:M,"*256GB*",Detail!C:C,"Lost",Detail!G:G,"HN") -> 2 | P34: =COUNTIFS(Detail!B:B,"LAPTOP",Detail!M:M,"*256GB*",Detail!C:C,"Sold",Detail!G:G,"HCM")+COUNTIFS(Detail!B:B,"LAPTOP",Detail!M:M,"*256GB*",Detail!C:C,"Sold",Detail!G:G,"HN") -> 1 | AB34: Lê Nhựt Thịnh
J35: 512GB | K35: =COUNTIFS(Detail!B:B,"LAPTOP",Detail!M:M,"*512GB*",Detail!G:G,"HCM")+COUNTIFS(Detail!B:B,"LAPTOP",Detail!M:M,"*512GB*",Detail!G:G,"HN") -> 38 | L35: =COUNTIFS(Detail!B:B,"LAPTOP",Detail!M:M,"*512GB*",Detail!C:C,"In Use",Detail!G:G,"HCM")+COUNTIFS(Detail!B:B,"LAPTOP",Detail!M:M,"*512GB*",Detail!C:C,"In Use",Detail!G:G,"HN") -> 24 | M35: =COUNTIFS(Detail!B:B,"LAPTOP",Detail!M:M,"*512GB*",Detail!C:C,"In Stock",Detail!G:G,"HCM")+COUNTIFS(Detail!B:B,"LAPTOP",Detail!M:M,"*512GB*",Detail!C:C,"In Stock",Detail!G:G,"HN") -> 11 | N35: =COUNTIFS(Detail!B:B,"LAPTOP",Detail!M:M,"*512GB*",Detail!C:C,"Damaged",Detail!G:G,"HCM")+COUNTIFS(Detail!B:B,"LAPTOP",Detail!M:M,"*512GB*",Detail!C:C,"Damaged",Detail!G:G,"HN") -> 0 | O35: =COUNTIFS(Detail!B:B,"LAPTOP",Detail!M:M,"*512GB*",Detail!C:C,"Lost",Detail!G:G,"HCM")+COUNTIFS(Detail!B:B,"LAPTOP",Detail!M:M,"*512GB*",Detail!C:C,"Lost",Detail!G:G,"HN") -> 0 | P35: =COUNTIFS(Detail!B:B,"LAPTOP",Detail!M:M,"*512GB*",Detail!C:C,"Sold",Detail!G:G,"HCM")+COUNTIFS(Detail!B:B,"LAPTOP",Detail!M:M,"*512GB*",Detail!C:C,"Sold",Detail!G:G,"HN") -> 1 | AB35: Lê Quang Hiếu
J36: 1TB | K36: =COUNTIFS(Detail!B:B,"LAPTOP",Detail!M:M,"*1TB*",Detail!G:G,"HCM")+COUNTIFS(Detail!B:B,"LAPTOP",Detail!M:M,"*1TB*",Detail!G:G,"HN") -> 2 | L36: =COUNTIFS(Detail!B:B,"LAPTOP",Detail!M:M,"*1TB*",Detail!C:C,"In Use",Detail!G:G,"HCM")+COUNTIFS(Detail!B:B,"LAPTOP",Detail!M:M,"*1TB*",Detail!C:C,"In Use",Detail!G:G,"HN") -> 1 | M36: =COUNTIFS(Detail!B:B,"LAPTOP",Detail!M:M,"*1TB*",Detail!C:C,"In Stock",Detail!G:G,"HCM")+COUNTIFS(Detail!B:B,"LAPTOP",Detail!M:M,"*1TB*",Detail!C:C,"In Stock",Detail!G:G,"HN") -> 1 | N36: =COUNTIFS(Detail!B:B,"LAPTOP",Detail!M:M,"*1TB*",Detail!C:C,"Damaged",Detail!G:G,"HCM")+COUNTIFS(Detail!B:B,"LAPTOP",Detail!M:M,"*1TB*",Detail!C:C,"Damaged",Detail!G:G,"HN") -> 0 | O36: =COUNTIFS(Detail!B:B,"LAPTOP",Detail!M:M,"*1TB*",Detail!C:C,"Lost",Detail!G:G,"HCM")+COUNTIFS(Detail!B:B,"LAPTOP",Detail!M:M,"*1TB*",Detail!C:C,"Lost",Detail!G:G,"HN") -> 0 | P36: =COUNTIFS(Detail!B:B,"LAPTOP",Detail!M:M,"*1TB*",Detail!C:C,"Sold",Detail!G:G,"HCM")+COUNTIFS(Detail!B:B,"LAPTOP",Detail!M:M,"*1TB*",Detail!C:C,"Sold",Detail!G:G,"HN") -> 0 | AB36: Lê Quý Vân Anh
J37: By Business Unit | AB37: Lê Thị Kim Anh
J38: Business Unit | K38: Quantity | L38: In Use | M38: In Stock | N38: Damaged | O38: Lost | P38: Sold | AB38: Lương Minh Hoàng
J39: Project | K39: =COUNTIFS(Detail!B:B,"LAPTOP",Detail!D:D,"Project",Detail!G:G,"HCM")+COUNTIFS(Detail!B:B,"LAPTOP",Detail!D:D,"Project",Detail!G:G,"HN") -> 25 | L39: =COUNTIFS(Detail!B:B,"LAPTOP",Detail!D:D,"Project",Detail!C:C,"In Use",Detail!G:G,"HCM")+COUNTIFS(Detail!B:B,"LAPTOP",Detail!D:D,"Project",Detail!C:C,"In Use",Detail!G:G,"HN") -> 25 | M39: =COUNTIFS(Detail!B:B,"LAPTOP",Detail!D:D,"Project",Detail!C:C,"In Stock",Detail!G:G,"HCM")+COUNTIFS(Detail!B:B,"LAPTOP",Detail!D:D,"Project",Detail!C:C,"In Stock",Detail!G:G,"HN") -> 0 | N39: =COUNTIFS(Detail!B:B,"LAPTOP",Detail!D:D,"Project",Detail!C:C,"Damaged",Detail!G:G,"HCM")+COUNTIFS(Detail!B:B,"LAPTOP",Detail!D:D,"Project",Detail!C:C,"Damaged",Detail!G:G,"HN") -> 0 | O39: =COUNTIFS(Detail!B:B,"LAPTOP",Detail!D:D,"Project",Detail!C:C,"Lost",Detail!G:G,"HCM")+COUNTIFS(Detail!B:B,"LAPTOP",Detail!D:D,"Project",Detail!C:C,"Lost",Detail!G:G,"HN") -> 0 | P39: =COUNTIFS(Detail!B:B,"LAPTOP",Detail!D:D,"Project",Detail!C:C,"Sold",Detail!G:G,"HCM")+COUNTIFS(Detail!B:B,"LAPTOP",Detail!D:D,"Project",Detail!C:C,"Sold",Detail!G:G,"HN") -> 0 | AB39: Mai Thị Cẩm Hà
J40: BO | K40: =COUNTIFS(Detail!B:B,"LAPTOP",Detail!D:D,"BO",Detail!G:G,"HCM")+COUNTIFS(Detail!B:B,"LAPTOP",Detail!D:D,"BO",Detail!G:G,"HN") -> 12 | L40: =COUNTIFS(Detail!B:B,"LAPTOP",Detail!D:D,"BO",Detail!C:C,"In Use",Detail!G:G,"HCM")+COUNTIFS(Detail!B:B,"LAPTOP",Detail!D:D,"BO",Detail!C:C,"In Use",Detail!G:G,"HN") -> 9 | M40: =COUNTIFS(Detail!B:B,"LAPTOP",Detail!D:D,"BO",Detail!C:C,"In Stock",Detail!G:G,"HCM")+COUNTIFS(Detail!B:B,"LAPTOP",Detail!D:D,"BO",Detail!C:C,"In Stock",Detail!G:G,"HN") -> 3 | N40: =COUNTIFS(Detail!B:B,"LAPTOP",Detail!D:D,"BO",Detail!C:C,"Damaged",Detail!G:G,"HCM")+COUNTIFS(Detail!B:B,"LAPTOP",Detail!D:D,"BO",Detail!C:C,"Damaged",Detail!G:G,"HN") -> 0 | O40: =COUNTIFS(Detail!B:B,"LAPTOP",Detail!D:D,"BO",Detail!C:C,"Lost",Detail!G:G,"HCM")+COUNTIFS(Detail!B:B,"LAPTOP",Detail!D:D,"BO",Detail!C:C,"Lost",Detail!G:G,"HN") -> 0 | P40: =COUNTIFS(Detail!B:B,"LAPTOP",Detail!D:D,"BO",Detail!C:C,"Sold",Detail!G:G,"HCM")+COUNTIFS(Detail!B:B,"LAPTOP",Detail!D:D,"BO",Detail!C:C,"Sold",Detail!G:G,"HN") -> 0 | AB40: Ngô Khánh Vy
...

Sheet Detail
A1: No | B1: Device Name | C1: Condition | D1: Business Unit | E1: Job Family | F1: Project | G1: Location | H1: Old Label | I1: Label | J1: Brand | K1: Description | L1: Chip | M1: Storage | N1: Intune | O1: License Win 11 Pro | P1: SN | Q1: Purchase date | R1: Vendor | S1: Price | T1: Invoice Number | U1: Retrieval Date | V1: Retrieval Reason | W1: Retriever Name | X1: Retriever ID | Y1: Retriever Job Tiitle | Z1: Retriever Dept | AA1: Returner Name | AB1: Returner ID | AC1: Returner Job Tittle | AD1: Returner Dept | AE1: Handover Date | AF1: Handover Staff | AG1: Handover Staff ID | AH1: Handover Staff Job Tiitle | AI1: Handover Staff Dept | AJ1: Employee Name | AK1: Employee ID | AL1: Employee Job Tittle | AM1: Employee Dept | AN1: Line Manager | AO1: Repair Date | AP1: Repair Details | AQ1: Note | AR1: Note 2 | AS1: Form No.
A2: =IF(B2<>"",ROW()-1,"") -> 1 | B2: LAPTOP | C2: In Use | D2: =INDEX(Employee!E:E,MATCH(AK2,Employee!B:B,0)) -> Project | E2: =INDEX(Employee!F:F,MATCH(AK2,Employee!B:B,0)) -> Tech | F2: =INDEX(Employee!G:G,MATCH(AK2,Employee!B:B,0)) -> Venture | G2: HCM | I2: LAP0001 | J2: Apple | K2: Macbook Pro M2 16GB | 256GB | L2: M2 | M2: =RIGHT(K2,5) -> 256GB | N2: TRUE | O2: FALSE | P2: GVXHT9W54J | Q2: 45618 | R2: VNG | S2: 24710000 | AF2: =INDEX(Employee!C:C,MATCH(AG2,Employee!B:B,0)) -> Nguyễn Viết Khải | AG2: khainv | AH2: =INDEX(Employee!D:D,MATCH(AG2,Employee!B:B,0)) -> Lead IT Support Engineer | AI2: =INDEX(Employee!F:F,MATCH(AG2,Employee!B:B,0)) -> Tech | AJ2: =INDEX(Employee!C:C,MATCH(AK2,Employee!B:B,0)) -> Bùi Quốc Thái | AK2: thaibq | AL2: =INDEX(Employee!D:D,MATCH(AK2,Employee!B:B,0)) -> Associate QC Engineer | AM2: =INDEX(Employee!F:F,MATCH(AK2,Employee!B:B,0)) -> Tech | AN2: =INDEX(Employee!H:H,MATCH(AK2,Employee!B:B,0)) -> Nguyễn Khánh Vy
A3: =IF(B3<>"",ROW()-1,"") -> 2 | B3: MONITOR | C3: In Use | D3: =INDEX(Employee!E:E,MATCH(AK3,Employee!B:B,0)) -> Project | E3: =INDEX(Employee!F:F,MATCH(AK3,Employee!B:B,0)) -> Tech | F3: =INDEX(Employee!G:G,MATCH(AK3,Employee!B:B,0)) -> Venture | G3: HCM | H3: MON16273 | I3: MON0001 | J3: Dell | K3: Dell P2425H 24 inches | N3: FALSE | O3: FALSE | P3: 331PK34 | Q3: 45622 | R3: VNG | S3: 4190287 | AF3: =INDEX(Employee!C:C,MATCH(AG3,Employee!B:B,0)) -> Nguyễn Viết Khải | AG3: khainv | AH3: =INDEX(Employee!D:D,MATCH(AG3,Employee!B:B,0)) -> Lead IT Support Engineer | AI3: =INDEX(Employee!F:F,MATCH(AG3,Employee!B:B,0)) -> Tech | AJ3: =INDEX(Employee!C:C,MATCH(AK3,Employee!B:B,0)) -> Bùi Quốc Thái | AK3: thaibq | AL3: =INDEX(Employee!D:D,MATCH(AK3,Employee!B:B,0)) -> Associate QC Engineer | AM3: =INDEX(Employee!F:F,MATCH(AK3,Employee!B:B,0)) -> Tech | AN3: =INDEX(Employee!H:H,MATCH(AK3,Employee!B:B,0)) -> Nguyễn Khánh Vy
A4: =IF(B4<>"",ROW()-1,"") -> 3 | B4: MOUSE | C4: In Use | D4: =INDEX(Employee!E:E,MATCH(AK4,Employee!B:B,0)) -> Project | E4: =INDEX(Employee!F:F,MATCH(AK4,Employee!B:B,0)) -> Tech | F4: =INDEX(Employee!G:G,MATCH(AK4,Employee!B:B,0)) -> Venture | G4: HCM | I4: MOU0001 | J4: Logitech | K4: Logitech M221 | N4: FALSE | O4: FALSE | P4: 2333LZXLJNF8 | Q4: 44462 | R4: VNG | S4: 36364 | AF4: =INDEX(Employee!C:C,MATCH(AG4,Employee!B:B,0)) -> Nguyễn Viết Khải | AG4: khainv | AH4: =INDEX(Employee!D:D,MATCH(AG4,Employee!B:B,0)) -> Lead IT Support Engineer | AI4: =INDEX(Employee!F:F,MATCH(AG4,Employee!B:B,0)) -> Tech | AJ4: =INDEX(Employee!C:C,MATCH(AK4,Employee!B:B,0)) -> Bùi Quốc Thái | AK4: thaibq | AL4: =INDEX(Employee!D:D,MATCH(AK4,Employee!B:B,0)) -> Associate QC Engineer | AM4: =INDEX(Employee!F:F,MATCH(AK4,Employee!B:B,0)) -> Tech | AN4: =INDEX(Employee!H:H,MATCH(AK4,Employee!B:B,0)) -> Nguyễn Khánh Vy
A5: =IF(B5<>"",ROW()-1,"") -> 4 | B5: LAPTOP | C5: In Stock | D5: =INDEX(Employee!E:E,MATCH(AK5,Employee!B:B,0)) -> #N/A | E5: =INDEX(Employee!F:F,MATCH(AK5,Employee!B:B,0)) -> #N/A | F5: =INDEX(Employee!G:G,MATCH(AK5,Employee!B:B,0)) -> #N/A | G5: HCM | I5: LAP0002 | J5: Lenovo | K5: Lenovo Thinkpad X390 i5 16GB | 256GB | L5: i5 | M5: =RIGHT(K5,5) -> 256GB | N5: TRUE | O5: TRUE | P5: PF1FUUQ0 | Q5: 43747 | R5: VNG | S5: 2660800 | AJ5: =INDEX(Employee!C:C,MATCH(AK5,Employee!B:B,0)) -> #N/A | AL5: =INDEX(Employee!D:D,MATCH(AK5,Employee!B:B,0)) -> #N/A | AM5: =INDEX(Employee!F:F,MATCH(AK5,Employee!B:B,0)) -> #N/A | AN5: =INDEX(Employee!H:H,MATCH(AK5,Employee!B:B,0)) -> #N/A
A6: =IF(B6<>"",ROW()-1,"") -> 5 | B6: MOUSE | C6: Damaged | D6: =INDEX(Employee!E:E,MATCH(AK6,Employee!B:B,0)) -> #N/A | E6: =INDEX(Employee!F:F,MATCH(AK6,Employee!B:B,0)) -> #N/A | F6: =INDEX(Employee!G:G,MATCH(AK6,Employee!B:B,0)) -> #N/A | G6: HCM | I6: MOU0002 | J6: Logitech | K6: Logitech M221 | N6: FALSE | O6: FALSE | Q6: 44536 | R6: VNG | S6: 21500 | AF6: =INDEX(Employee!C:C,MATCH(AG6,Employee!B:B,0)) -> Nguyễn Viết Khải | AG6: khainv | AH6: =INDEX(Employee!D:D,MATCH(AG6,Employee!B:B,0)) -> Lead IT Support Engineer | AI6: =INDEX(Employee!F:F,MATCH(AG6,Employee!B:B,0)) -> Tech | AJ6: =INDEX(Employee!C:C,MATCH(AK6,Employee!B:B,0)) -> #N/A | AL6: =INDEX(Employee!D:D,MATCH(AK6,Employee!B:B,0)) -> #N/A | AM6: =INDEX(Employee!F:F,MATCH(AK6,Employee!B:B,0)) -> #N/A | AN6: =INDEX(Employee!H:H,MATCH(AK6,Employee!B:B,0)) -> #N/A
A7: =IF(B7<>"",ROW()-1,"") -> 6 | B7: LAPTOP | C7: In Use | D7: =INDEX(Employee!E:E,MATCH(AK7,Employee!B:B,0)) -> 0 | E7: =INDEX(Employee!F:F,MATCH(AK7,Employee!B:B,0)) -> Tech | F7: =INDEX(Employee!G:G,MATCH(AK7,Employee!B:B,0)) -> 0 | G7: IPL | I7: LAP0003 | J7: Apple | K7: Macbook Pro M1 16GB | 256GB | L7: M1 | M7: =RIGHT(K7,5) -> 256GB | N7: FALSE | O7: FALSE | P7: FVFHW06QQ05N | Q7: 22/07/2022 | R7: VNG | S7: 6683562 | AF7: =INDEX(Employee!C:C,MATCH(AG7,Employee!B:B,0)) -> Nguyễn Viết Khải | AG7: khainv | AH7: =INDEX(Employee!D:D,MATCH(AG7,Employee!B:B,0)) -> Lead IT Support Engineer | AI7: =INDEX(Employee!F:F,MATCH(AG7,Employee!B:B,0)) -> Tech | AJ7: =INDEX(Employee!C:C,MATCH(AK7,Employee!B:B,0)) -> Lê Nhựt Thịnh | AK7: thinhln | AL7: =INDEX(Employee!D:D,MATCH(AK7,Employee!B:B,0)) -> Software Engineer | AM7: =INDEX(Employee!F:F,MATCH(AK7,Employee!B:B,0)) -> Tech | AN7: =INDEX(Employee!H:H,MATCH(AK7,Employee!B:B,0)) -> Trần Triệu Dương (duongtt5)
A8: =IF(B8<>"",ROW()-1,"") -> 7 | B8: LAPTOP | C8: In Stock | D8: =INDEX(Employee!E:E,MATCH(AK8,Employee!B:B,0)) -> #N/A | E8: =INDEX(Employee!F:F,MATCH(AK8,Employee!B:B,0)) -> #N/A | F8: =INDEX(Employee!G:G,MATCH(AK8,Employee!B:B,0)) -> #N/A | G8: HCM | I8: LAP0004 | J8: Apple | K8: Macbook Pro M1 16GB | 256GB | L8: M1 | M8: =RIGHT(K8,5) -> 256GB | N8: TRUE | O8: FALSE | P8: C02HC0JVQ05N | Q8: 44999 | R8: VNG | S8: 3379715 | AF8: =INDEX(Employee!C:C,MATCH(AG8,Employee!B:B,0)) -> Nguyễn Viết Khải | AG8: khainv | AH8: =INDEX(Employee!D:D,MATCH(AG8,Employee!B:B,0)) -> Lead IT Support Engineer | AI8: =INDEX(Employee!F:F,MATCH(AG8,Employee!B:B,0)) -> Tech | AJ8: =INDEX(Employee!C:C,MATCH(AK8,Employee!B:B,0)) -> #N/A | AL8: =INDEX(Employee!D:D,MATCH(AK8,Employee!B:B,0)) -> #N/A | AM8: =INDEX(Employee!F:F,MATCH(AK8,Employee!B:B,0)) -> #N/A | AN8: =INDEX(Employee!H:H,MATCH(AK8,Employee!B:B,0)) -> #N/A | AS8: hieucc2
A9: =IF(B9<>"",ROW()-1,"") -> 8 | B9: MOUSE | C9: Damaged | D9: =INDEX(Employee!E:E,MATCH(AK9,Employee!B:B,0)) -> #N/A | E9: =INDEX(Employee!F:F,MATCH(AK9,Employee!B:B,0)) -> #N/A | F9: =INDEX(Employee!G:G,MATCH(AK9,Employee!B:B,0)) -> #N/A | G9: HCM | I9: MOU0003 | J9: Logitech | K9: Logitech M221 | N9: FALSE | O9: FALSE | P9: 2333LZXH2X68 | Q9: 44621 | R9: VNG | S9: 21000 | AF9: =INDEX(Employee!C:C,MATCH(AG9,Employee!B:B,0)) -> Nguyễn Viết Khải | AG9: khainv | AH9: =INDEX(Employee!D:D,MATCH(AG9,Employee!B:B,0)) -> Lead IT Support Engineer | AI9: =INDEX(Employee!F:F,MATCH(AG9,Employee!B:B,0)) -> Tech | AJ9: =INDEX(Employee!C:C,MATCH(AK9,Employee!B:B,0)) -> #N/A | AL9: =INDEX(Employee!D:D,MATCH(AK9,Employee!B:B,0)) -> #N/A | AM9: =INDEX(Employee!F:F,MATCH(AK9,Employee!B:B,0)) -> #N/A | AN9: =INDEX(Employee!H:H,MATCH(AK9,Employee!B:B,0)) -> #N/A | AS9: hieucc2
A10: =IF(B10<>"",ROW()-1,"") -> 9 | B10: LAPTOP | C10: In Use | D10: =INDEX(Employee!E:E,MATCH(AK10,Employee!B:B,0)) -> Project | E10: =INDEX(Employee!F:F,MATCH(AK10,Employee!B:B,0)) -> Tech | F10: =INDEX(Employee!G:G,MATCH(AK10,Employee!B:B,0)) -> Venture | G10: HCM | I10: LAP0005 | J10: Apple | K10: Macbook Pro M1 16GB | 256GB | L10: M1 | M10: =RIGHT(K10,5) -> 256GB | N10: TRUE | O10: FALSE | P10: C02G12P8Q05N | Q10: 44831 | R10: VNG | S10: 3300000 | AF10: =INDEX(Employee!C:C,MATCH(AG10,Employee!B:B,0)) -> Nguyễn Viết Khải | AG10: khainv | AH10: =INDEX(Employee!D:D,MATCH(AG10,Employee!B:B,0)) -> Lead IT Support Engineer | AI10: =INDEX(Employee!F:F,MATCH(AG10,Employee!B:B,0)) -> Tech | AJ10: =INDEX(Employee!C:C,MATCH(AK10,Employee!B:B,0)) -> Huỳnh Thúy Diễm | AK10: diemht | AL10: =INDEX(Employee!D:D,MATCH(AK10,Employee!B:B,0)) -> Fresher Business Analyst | AM10: =INDEX(Employee!F:F,MATCH(AK10,Employee!B:B,0)) -> Tech | AN10: =INDEX(Employee!H:H,MATCH(AK10,Employee!B:B,0)) -> Nguyễn Khánh Vy
A11: =IF(B11<>"",ROW()-1,"") -> 10 | B11: LAPTOP | C11: In Use | D11: =INDEX(Employee!E:E,MATCH(AK11,Employee!B:B,0)) -> 0 | E11: =INDEX(Employee!F:F,MATCH(AK11,Employee!B:B,0)) -> Tech | F11: =INDEX(Employee!G:G,MATCH(AK11,Employee!B:B,0)) -> 0 | G11: IPL | I11: LAP0006 | J11: Apple | K11: Macbook Pro M1 16GB | 256GB | L11: M1 | M11: =RIGHT(K11,5) -> 256GB | N11: FALSE | O11: FALSE | P11: C02H70QTQ05N | Q11: 44807 | R11: VNG | S11: 3245455 | AF11: =INDEX(Employee!C:C,MATCH(AG11,Employee!B:B,0)) -> Nguyễn Viết Khải | AG11: khainv | AH11: =INDEX(Employee!D:D,MATCH(AG11,Employee!B:B,0)) -> Lead IT Support Engineer | AI11: =INDEX(Employee!F:F,MATCH(AG11,Employee!B:B,0)) -> Tech | AJ11: =INDEX(Employee!C:C,MATCH(AK11,Employee!B:B,0)) -> Nguyễn Ngọc Châu Sang | AK11: sangnnc | AL11: =INDEX(Employee!D:D,MATCH(AK11,Employee!B:B,0)) -> Solutions Architect | AM11: =INDEX(Employee!F:F,MATCH(AK11,Employee!B:B,0)) -> Tech | AN11: =INDEX(Employee!H:H,MATCH(AK11,Employee!B:B,0)) -> Dương Huỳnh Nghĩa (nghiadh)
A12: =IF(B12<>"",ROW()-1,"") -> 11 | B12: LAPTOP | C12: In Stock | D12: =INDEX(Employee!E:E,MATCH(AK12,Employee!B:B,0)) -> #N/A | E12: =INDEX(Employee!F:F,MATCH(AK12,Employee!B:B,0)) -> #N/A | F12: =INDEX(Employee!G:G,MATCH(AK12,Employee!B:B,0)) -> #N/A | G12: HCM | I12: LAP0007 | J12: Lenovo | K12: Lenovo ThinkPad X13 i5 16GB | 256GB | L12: i5 | M12: =RIGHT(K12,5) -> 256GB | N12: TRUE | O12: FALSE | P12: PC1MHDDG | Q12: 44115 | R12: VNG | S12: 2644500 | AF12: =INDEX(Employee!C:C,MATCH(AG12,Employee!B:B,0)) -> Nguyễn Viết Khải | AG12: khainv | AH12: =INDEX(Employee!D:D,MATCH(AG12,Employee!B:B,0)) -> Lead IT Support Engineer | AI12: =INDEX(Employee!F:F,MATCH(AG12,Employee!B:B,0)) -> Tech | AJ12: =INDEX(Employee!C:C,MATCH(AK12,Employee!B:B,0)) -> #N/A | AL12: =INDEX(Employee!D:D,MATCH(AK12,Employee!B:B,0)) -> #N/A | AM12: =INDEX(Employee!F:F,MATCH(AK12,Employee!B:B,0)) -> #N/A | AN12: =INDEX(Employee!H:H,MATCH(AK12,Employee!B:B,0)) -> #N/A
A13: =IF(B13<>"",ROW()-1,"") -> 12 | B13: MOUSE | C13: In Use | D13: =INDEX(Employee!E:E,MATCH(AK13,Employee!B:B,0)) -> 0 | E13: =INDEX(Employee!F:F,MATCH(AK13,Employee!B:B,0)) -> Tech | F13: =INDEX(Employee!G:G,MATCH(AK13,Employee!B:B,0)) -> 0 | G13: IPL | I13: MOU0004 | J13: Logitech | K13: Logitech M221 | N13: FALSE | O13: FALSE | Q13: 44621 | R13: VNG | S13: 21000 | AF13: =INDEX(Employee!C:C,MATCH(AG13,Employee!B:B,0)) -> Nguyễn Viết Khải | AG13: khainv | AH13: =INDEX(Employee!D:D,MATCH(AG13,Employee!B:B,0)) -> Lead IT Support Engineer | AI13: =INDEX(Employee!F:F,MATCH(AG13,Employee!B:B,0)) -> Tech | AJ13: =INDEX(Employee!C:C,MATCH(AK13,Employee!B:B,0)) -> Nguyễn Ngọc Châu Sang | AK13: sangnnc | AL13: =INDEX(Employee!D:D,MATCH(AK13,Employee!B:B,0)) -> Solutions Architect | AM13: =INDEX(Employee!F:F,MATCH(AK13,Employee!B:B,0)) -> Tech | AN13: =INDEX(Employee!H:H,MATCH(AK13,Employee!B:B,0)) -> Dương Huỳnh Nghĩa (nghiadh)
A14: =IF(B14<>"",ROW()-1,"") -> 13 | B14: LAPTOP | C14: In Use | D14: =INDEX(Employee!E:E,MATCH(AK14,Employee!B:B,0)) -> 0 | E14: =INDEX(Employee!F:F,MATCH(AK14,Employee!B:B,0)) -> Tech | F14: =INDEX(Employee!G:G,MATCH(AK14,Employee!B:B,0)) -> 0 | G14: IPL | I14: LAP0008 | J14: Lenovo | K14: Lenovo ThinkPad T14 i5 32GB | 256GB | L14: i5 | M14: =RIGHT(K14,5) -> 256GB | N14: FALSE | O14: TRUE | P14: PF50YJSJ | Q14: 45491 | R14: VNG | S14: 25408445 | AF14: =INDEX(Employee!C:C,MATCH(AG14,Employee!B:B,0)) -> Nguyễn Viết Khải | AG14: khainv | AH14: =INDEX(Employee!D:D,MATCH(AG14,Employee!B:B,0)) -> Lead IT Support Engineer | AI14: =INDEX(Employee!F:F,MATCH(AG14,Employee!B:B,0)) -> Tech | AJ14: =INDEX(Employee!C:C,MATCH(AK14,Employee!B:B,0)) -> Nguyễn Thanh Lê | AK14: lent2 | AL14: =INDEX(Employee!D:D,MATCH(AK14,Employee!B:B,0)) -> Senior GIS Specialist | AM14: =INDEX(Employee!F:F,MATCH(AK14,Employee!B:B,0)) -> Tech | AN14: =INDEX(Employee!H:H,MATCH(AK14,Employee!B:B,0)) -> Dương Huỳnh Nghĩa (nghiadh)
A15: =IF(B15<>"",ROW()-1,"") -> 14 | B15: MOUSE | C15: In Use | D15: =INDEX(Employee!E:E,MATCH(AK15,Employee!B:B,0)) -> Project | E15: =INDEX(Employee!F:F,MATCH(AK15,Employee!B:B,0)) -> Data | F15: =INDEX(Employee!G:G,MATCH(AK15,Employee!B:B,0)) -> Resource Pool | G15: HCM | H15: MOU15343 | I15: MOU0005 | J15: Logitech | K15: Logitech M221 | N15: FALSE | O15: FALSE | P15: 2431ZEB6EG48 | Q15: 44621 | R15: VNG | S15: 21000 | AF15: =INDEX(Employee!C:C,MATCH(AG15,Employee!B:B,0)) -> Nguyễn Viết Khải | AG15: khainv | AH15: =INDEX(Employee!D:D,MATCH(AG15,Employee!B:B,0)) -> Lead IT Support Engineer | AI15: =INDEX(Employee!F:F,MATCH(AG15,Employee!B:B,0)) -> Tech | AJ15: =INDEX(Employee!C:C,MATCH(AK15,Employee!B:B,0)) -> Phạm Bằng | AK15: bangp | AL15: =INDEX(Employee!D:D,MATCH(AK15,Employee!B:B,0)) -> Fresher Data Engineer | AM15: =INDEX(Employee!F:F,MATCH(AK15,Employee!B:B,0)) -> Data | AN15: =INDEX(Employee!H:H,MATCH(AK15,Employee!B:B,0)) -> Đoàn Hải Nam
A16: =IF(B16<>"",ROW()-1,"") -> 15 | B16: LAPTOP | C16: In Stock | D16: =INDEX(Employee!E:E,MATCH(AK16,Employee!B:B,0)) -> #N/A | E16: =INDEX(Employee!F:F,MATCH(AK16,Employee!B:B,0)) -> #N/A | F16: =INDEX(Employee!G:G,MATCH(AK16,Employee!B:B,0)) -> #N/A | G16: HCM | I16: LAP0009 | J16: Lenovo | K16: Lenovo ThinkPad X13 i5 16GB | 256GB | L16: i5 | M16: =RIGHT(K16,5) -> 256GB | N16: TRUE | O16: TRUE | P16: PC1ZJRVM | Q16: 44357 | R16: VNG | S16: 2597900 | AF16: =INDEX(Employee!C:C,MATCH(AG16,Employee!B:B,0)) -> Nguyễn Viết Khải | AG16: khainv | AH16: =INDEX(Employee!D:D,MATCH(AG16,Employee!B:B,0)) -> Lead IT Support Engineer | AI16: =INDEX(Employee!F:F,MATCH(AG16,Employee!B:B,0)) -> Tech | AJ16: =INDEX(Employee!C:C,MATCH(AK16,Employee!B:B,0)) -> #N/A | AL16: =INDEX(Employee!D:D,MATCH(AK16,Employee!B:B,0)) -> #N/A | AM16: =INDEX(Employee!F:F,MATCH(AK16,Employee!B:B,0)) -> #N/A | AN16: =INDEX(Employee!H:H,MATCH(AK16,Employee!B:B,0)) -> #N/A
A17: =IF(B17<>"",ROW()-1,"") -> 16 | B17: MOUSE | C17: Damaged | D17: =INDEX(Employee!E:E,MATCH(AK17,Employee!B:B,0)) -> 0 | E17: =INDEX(Employee!F:F,MATCH(AK17,Employee!B:B,0)) -> Tech | F17: =INDEX(Employee!G:G,MATCH(AK17,Employee!B:B,0)) -> 0 | G17: HCM | H17: MOU15235 | I17: MOU0006 | J17: Logitech | K17: Logitech M221 | N17: FALSE | O17: FALSE | Q17: 44621 | R17: VNG | S17: 21000 | AF17: =INDEX(Employee!C:C,MATCH(AG17,Employee!B:B,0)) -> Nguyễn Viết Khải | AG17: khainv | AH17: =INDEX(Employee!D:D,MATCH(AG17,Employee!B:B,0)) -> Lead IT Support Engineer | AI17: =INDEX(Employee!F:F,MATCH(AG17,Employee!B:B,0)) -> Tech | AJ17: =INDEX(Employee!C:C,MATCH(AK17,Employee!B:B,0)) -> Nguyễn Thanh Lê | AK17: lent2 | AL17: =INDEX(Employee!D:D,MATCH(AK17,Employee!B:B,0)) -> Senior GIS Specialist | AM17: =INDEX(Employee!F:F,MATCH(AK17,Employee!B:B,0)) -> Tech | AN17: =INDEX(Employee!H:H,MATCH(AK17,Employee!B:B,0)) -> Dương Huỳnh Nghĩa (nghiadh)
A18: =IF(B18<>"",ROW()-1,"") -> 17 | B18: LAPTOP | C18: In Use | D18: =INDEX(Employee!E:E,MATCH(AK18,Employee!B:B,0)) -> 0 | E18: =INDEX(Employee!F:F,MATCH(AK18,Employee!B:B,0)) -> Tech | F18: =INDEX(Employee!G:G,MATCH(AK18,Employee!B:B,0)) -> 0 | G18: IPL | I18: LAP0010 | J18: Apple | K18: Macbook Pro M2 16GB | 512GB | L18: M2 | M18: =RIGHT(K18,5) -> 512GB | N18: FALSE | O18: FALSE | P18: DDJ4HW2P2C | Q18: 45252 | R18: VNG | S18: 24710000 | AF18: =INDEX(Employee!C:C,MATCH(AG18,Employee!B:B,0)) -> Nguyễn Viết Khải | AG18: khainv | AH18: =INDEX(Employee!D:D,MATCH(AG18,Employee!B:B,0)) -> Lead IT Support Engineer | AI18: =INDEX(Employee!F:F,MATCH(AG18,Employee!B:B,0)) -> Tech | AJ18: =INDEX(Employee!C:C,MATCH(AK18,Employee!B:B,0)) -> Đào Xuân Tùng | AK18: tungdx2 | AL18: =INDEX(Employee!D:D,MATCH(AK18,Employee!B:B,0)) -> Software Engineer | AM18: =INDEX(Employee!F:F,MATCH(AK18,Employee!B:B,0)) -> Tech | AN18: =INDEX(Employee!H:H,MATCH(AK18,Employee!B:B,0)) -> Trần Triệu Dương (duongtt5)
A19: =IF(B19<>"",ROW()-1,"") -> 18 | B19: MOUSE | C19: Damaged | D19: =INDEX(Employee!E:E,MATCH(AK19,Employee!B:B,0)) -> 0 | E19: =INDEX(Employee!F:F,MATCH(AK19,Employee!B:B,0)) -> OP | F19: =INDEX(Employee!G:G,MATCH(AK19,Employee!B:B,0)) -> 0 | G19: HCM | I19: MOU0007 | J19: Logitech | K19: Logitech M221 | N19: FALSE | O19: FALSE | P19: 2212LZM7T1A8 | Q19: 44621 | R19: VNG | S19: 21000 | AF19: =INDEX(Employee!C:C,MATCH(AG19,Employee!B:B,0)) -> Nguyễn Viết Khải | AG19: khainv | AH19: =INDEX(Employee!D:D,MATCH(AG19,Employee!B:B,0)) -> Lead IT Support Engineer | AI19: =INDEX(Employee!F:F,MATCH(AG19,Employee!B:B,0)) -> Tech | AJ19: =INDEX(Employee!C:C,MATCH(AK19,Employee!B:B,0)) -> Hà Quốc Nguyên | AK19: nguyenhq | AL19: =INDEX(Employee!D:D,MATCH(AK19,Employee!B:B,0)) -> Technical Support Engineer | AM19: =INDEX(Employee!F:F,MATCH(AK19,Employee!B:B,0)) -> OP | AN19: =INDEX(Employee!H:H,MATCH(AK19,Employee!B:B,0)) -> Chu Văn Toàn (ToanCV)
A20: =IF(B20<>"",ROW()-1,"") -> 19 | B20: LAPTOP | C20: In Use | D20: =INDEX(Employee!E:E,MATCH(AK20,Employee!B:B,0)) -> Project | E20: =INDEX(Employee!F:F,MATCH(AK20,Employee!B:B,0)) -> Tech | F20: =INDEX(Employee!G:G,MATCH(AK20,Employee!B:B,0)) -> Resource Pool | G20: HCM | I20: LAP0011 | J20: Lenovo | K20: Lenovo ThinkPad T490 i5 16GB | 256GB | L20: i5 | M20: =RIGHT(K20,5) -> 256GB | N20: TRUE | O20: FALSE | P20: PF2B20VE | Q20: 44043 | R20: VNG | S20: 2565000 | AF20: =INDEX(Employee!C:C,MATCH(AG20,Employee!B:B,0)) -> Nguyễn Viết Khải | AG20: khainv | AH20: =INDEX(Employee!D:D,MATCH(AG20,Employee!B:B,0)) -> Lead IT Support Engineer | AI20: =INDEX(Employee!F:F,MATCH(AG20,Employee!B:B,0)) -> Tech | AJ20: =INDEX(Employee!C:C,MATCH(AK20,Employee!B:B,0)) -> Huỳnh Nguyên Phương | AK20: phuonghn | AL20: =INDEX(Employee!D:D,MATCH(AK20,Employee!B:B,0)) -> Hardware Designer | AM20: =INDEX(Employee!F:F,MATCH(AK20,Employee!B:B,0)) -> Tech | AN20: =INDEX(Employee!H:H,MATCH(AK20,Employee!B:B,0)) -> Đoàn Hải Nam
A21: =IF(B21<>"",ROW()-1,"") -> 20 | B21: LAPTOP | C21: Damaged | D21: =INDEX(Employee!E:E,MATCH(AK21,Employee!B:B,0)) -> #N/A | E21: =INDEX(Employee!F:F,MATCH(AK21,Employee!B:B,0)) -> #N/A | F21: =INDEX(Employee!G:G,MATCH(AK21,Employee!B:B,0)) -> #N/A | G21: HCM | I21: LAP0012 | J21: Lenovo | K21: Lenovo ThinkPad T14 i5 16GB | 256GB | L21: i5 | M21: =RIGHT(K21,5) -> 256GB | N21: TRUE | O21: FALSE | P21: PF2GP2ZD | Q21: 44204 | R21: VNG | S21: 2534220 | AF21: =INDEX(Employee!C:C,MATCH(AG21,Employee!B:B,0)) -> Nguyễn Viết Khải | AG21: khainv | AH21: =INDEX(Employee!D:D,MATCH(AG21,Employee!B:B,0)) -> Lead IT Support Engineer | AI21: =INDEX(Employee!F:F,MATCH(AG21,Employee!B:B,0)) -> Tech | AJ21: =INDEX(Employee!C:C,MATCH(AK21,Employee!B:B,0)) -> #N/A | AL21: =INDEX(Employee!D:D,MATCH(AK21,Employee!B:B,0)) -> #N/A | AM21: =INDEX(Employee!F:F,MATCH(AK21,Employee!B:B,0)) -> #N/A | AN21: =INDEX(Employee!H:H,MATCH(AK21,Employee!B:B,0)) -> #N/A | AQ21: Lỗi MainBoard +Màn Hình chớp
A22: =IF(B22<>"",ROW()-1,"") -> 21 | B22: MOUSE | C22: In Use | D22: =INDEX(Employee!E:E,MATCH(AK22,Employee!B:B,0)) -> 0 | E22: =INDEX(Employee!F:F,MATCH(AK22,Employee!B:B,0)) -> Tech | F22: =INDEX(Employee!G:G,MATCH(AK22,Employee!B:B,0)) -> 0 | G22: IPL | I22: MOU0008 | J22: Logitech | K22: Logitech M221 | N22: FALSE | O22: FALSE | Q22: 44699 | R22: VNG | S22: 20900 | AF22: =INDEX(Employee!C:C,MATCH(AG22,Employee!B:B,0)) -> Nguyễn Viết Khải | AG22: khainv | AH22: =INDEX(Employee!D:D,MATCH(AG22,Employee!B:B,0)) -> Lead IT Support Engineer | AI22: =INDEX(Employee!F:F,MATCH(AG22,Employee!B:B,0)) -> Tech | AJ22: =INDEX(Employee!C:C,MATCH(AK22,Employee!B:B,0)) -> Đào Xuân Tùng | AK22: tungdx2 | AL22: =INDEX(Employee!D:D,MATCH(AK22,Employee!B:B,0)) -> Software Engineer | AM22: =INDEX(Employee!F:F,MATCH(AK22,Employee!B:B,0)) -> Tech | AN22: =INDEX(Employee!H:H,MATCH(AK22,Employee!B:B,0)) -> Trần Triệu Dương (duongtt5)
A23: =IF(B23<>"",ROW()-1,"") -> 22 | B23: LAPTOP | C23: In Stock | D23: =INDEX(Employee!E:E,MATCH(AK23,Employee!B:B,0)) -> #N/A | E23: =INDEX(Employee!F:F,MATCH(AK23,Employee!B:B,0)) -> #N/A | F23: =INDEX(Employee!G:G,MATCH(AK23,Employee!B:B,0)) -> #N/A | G23: HCM | I23: LAP0013 | J23: Apple | K23: Macbook Pro M1 16GB | 256GB | L23: M1 | M23: =RIGHT(K23,5) -> 256GB | N23: TRUE | O23: FALSE | P23: FVFHQ8MMQ05N | Q23: 44743 | R23: VNG | S23: 5512828 | AF23: =INDEX(Employee!C:C,MATCH(AG23,Employee!B:B,0)) -> Nguyễn Viết Khải | AG23: khainv | AH23: =INDEX(Employee!D:D,MATCH(AG23,Employee!B:B,0)) -> Lead IT Support Engineer | AI23: =INDEX(Employee!F:F,MATCH(AG23,Employee!B:B,0)) -> Tech | AJ23: =INDEX(Employee!C:C,MATCH(AK23,Employee!B:B,0)) -> #N/A | AL23: =INDEX(Employee!D:D,MATCH(AK23,Employee!B:B,0)) -> #N/A | AM23: =INDEX(Employee!F:F,MATCH(AK23,Employee!B:B,0)) -> #N/A | AN23: =INDEX(Employee!H:H,MATCH(AK23,Employee!B:B,0)) -> #N/A
A24: =IF(B24<>"",ROW()-1,"") -> 23 | B24: MOUSE | C24: Damaged | D24: =INDEX(Employee!E:E,MATCH(AK24,Employee!B:B,0)) -> Undirect IT Staff | E24: =INDEX(Employee!F:F,MATCH(AK24,Employee!B:B,0)) -> Tech | F24: =INDEX(Employee!G:G,MATCH(AK24,Employee!B:B,0)) -> Odoo | G24: HCM | H24: MOU15330 | I24: MOU0009 | J24: Logitech | K24: Logitech M221 | N24: FALSE | O24: FALSE | P24: 2345LZXET5L8 | Q24: 44727 | R24: VNG | S24: 20900 | AF24: =INDEX(Employee!C:C,MATCH(AG24,Employee!B:B,0)) -> Nguyễn Viết Khải | AG24: khainv | AH24: =INDEX(Employee!D:D,MATCH(AG24,Employee!B:B,0)) -> Lead IT Support Engineer | AI24: =INDEX(Employee!F:F,MATCH(AG24,Employee!B:B,0)) -> Tech | AJ24: =INDEX(Employee!C:C,MATCH(AK24,Employee!B:B,0)) -> Nguyễn Lâm Khánh Quỳnh | AK24: quynhnlk | AL24: =INDEX(Employee!D:D,MATCH(AK24,Employee!B:B,0)) -> Business Analyst | AM24: =INDEX(Employee!F:F,MATCH(AK24,Employee!B:B,0)) -> Tech | AN24: =INDEX(Employee!H:H,MATCH(AK24,Employee!B:B,0)) -> Dương Phạm Thành Công (congdpt)
A25: =IF(B25<>"",ROW()-1,"") -> 24 | B25: LAPTOP | C25: In Stock | D25: =INDEX(Employee!E:E,MATCH(AK25,Employee!B:B,0)) -> #N/A | E25: =INDEX(Employee!F:F,MATCH(AK25,Employee!B:B,0)) -> #N/A | F25: =INDEX(Employee!G:G,MATCH(AK25,Employee!B:B,0)) -> #N/A | G25: HCM | I25: LAP0014 | J25: Apple | K25: Macbook Pro M1 16GB | 256GB | L25: M1 | M25: =RIGHT(K25,5) -> 256GB | N25: TRUE | O25: FALSE | P25: FVFHQ8TJQ05N | Q25: 44743 | R25: VNG | S25: 5512828 | AF25: =INDEX(Employee!C:C,MATCH(AG25,Employee!B:B,0)) -> Nguyễn Viết Khải | AG25: khainv | AH25: =INDEX(Employee!D:D,MATCH(AG25,Employee!B:B,0)) -> Lead IT Support Engineer | AI25: =INDEX(Employee!F:F,MATCH(AG25,Employee!B:B,0)) -> Tech | AJ25: =INDEX(Employee!C:C,MATCH(AK25,Employee!B:B,0)) -> #N/A | AL25: =INDEX(Employee!D:D,MATCH(AK25,Employee!B:B,0)) -> #N/A | AM25: =INDEX(Employee!F:F,MATCH(AK25,Employee!B:B,0)) -> #N/A | AN25: =INDEX(Employee!H:H,MATCH(AK25,Employee!B:B,0)) -> #N/A
A26: =IF(B26<>"",ROW()-1,"") -> 25 | B26: LAPTOP | C26: In Stock | D26: =INDEX(Employee!E:E,MATCH(AK26,Employee!B:B,0)) -> #N/A | E26: =INDEX(Employee!F:F,MATCH(AK26,Employee!B:B,0)) -> #N/A | F26: =INDEX(Employee!G:G,MATCH(AK26,Employee!B:B,0)) -> #N/A | G26: HCM | H26: LAP60663 | I26: LAP0015 | J26: Lenovo | K26: Lenovo ThinkPad T14 i5 16GB | 256GB | L26: i5 | M26: =RIGHT(K26,5) -> 256GB | N26: TRUE | O26: TRUE | P26: PF2JY588 | Q26: 44272 | R26: VNG | S26: 2545300 | AF26: =INDEX(Employee!C:C,MATCH(AG26,Employee!B:B,0)) -> Nguyễn Viết Khải | AG26: khainv | AH26: =INDEX(Employee!D:D,MATCH(AG26,Employee!B:B,0)) -> Lead IT Support Engineer | AI26: =INDEX(Employee!F:F,MATCH(AG26,Employee!B:B,0)) -> Tech | AJ26: =INDEX(Employee!C:C,MATCH(AK26,Employee!B:B,0)) -> #N/A | AL26: =INDEX(Employee!D:D,MATCH(AK26,Employee!B:B,0)) -> #N/A | AM26: =INDEX(Employee!F:F,MATCH(AK26,Employee!B:B,0)) -> #N/A | AN26: =INDEX(Employee!H:H,MATCH(AK26,Employee!B:B,0)) -> #N/A
